<?xml version="1.0" ?>
<sdf version="1.4">
  <model name="robot">
    <link name="gripper_l">
      <pose>0 -0.5 0 0 0 0</pose>
      <gravity>0</gravity>
      <inertial>
        <pose>0 0 0 0 0 0</pose>
        <inertia>
          <ixx>0.0016667</ixx>
          <ixy>0</ixy>
          <ixz>0</ixz>
          <iyy>0.0016667</iyy>
          <iyz>0</iyz>
          <izz>0.0016667</izz>
        </inertia>
        <mass>1.0</mass>
      </inertial>
      <collision name="gripper_l_col">
        <pose>0 0 0 0 0 0</pose>
        <geometry>
          <box>
            <size>0.1 0.1 0.1</size>
          </box>
        </geometry>
      </collision>
      <visual name="gripper_l_vis">
        <pose>0 0 0 0 0 0</pose>
        <geometry>
          <box>
            <size>0.1 0.1 0.1</size>
          </box>
        </geometry>
        <material>
          <script>
            <uri>file://media/materials/scripts/gazebo.material</uri>
            <name>Gazebo/Blue</name>
          </script>
        </material>
      </visual>
    </link>
    <link name="gripper_r">
      <pose>0 0.5 0 0 0 0</pose>
      <gravity>0</gravity>
      <inertial>
        <pose>0 0 0 0 0 0</pose>
        <inertia>
          <ixx>0.0016667</ixx>
          <ixy>0</ixy>
          <ixz>0</ixz>
          <iyy>0.0016667</iyy>
          <iyz>0</iyz>
          <izz>0.0016667</izz>
        </inertia>
        <mass>1.0</mass>
      </inertial>
      <collision name="gripper_r_col">
        <pose>0 0 0 0 0 0</pose>
        <geometry>
          <box>
            <size>0.1 0.1 0.1</size>
          </box>
        </geometry>
      </collision>
      <visual name="gripper_r_vis">
        <pose>0 0 0 0 0 0</pose>
        <geometry>
          <box>
            <size>0.1 0.1 0.1</size>
          </box>
        </geometry>
        <material>
          <script>
            <uri>file://media/materials/scripts/gazebo.material</uri>
            <name>Gazebo/Blue</name>
          </script>
        </material>
      </visual>
    </link>

    <joint name="actuator" type="prismatic"> 
      <parent>gripper_l</parent>
      <child>gripper_r</child>
      <axis>
        <dynamics>
          <damping>0.0</damping>
          <friction>0.0</friction>
        </dynamics>
        <xyz>0 1 0</xyz>
      </axis>
    </joint>

    <plugin name='block-grasp-controller' filename='libblock-grasp-controller.so'>
    </plugin>

  </model>
</sdf>
